{
 "cells": [
  {
   "cell_type": "code",
   "execution_count": 1,
   "id": "7b917bb5-b03c-4a71-9ed4-cebf3aaf5134",
   "metadata": {},
   "outputs": [
    {
     "name": "stderr",
     "output_type": "stream",
     "text": [
      "2023-06-07 07:06:22.450972: I tensorflow/core/platform/cpu_feature_guard.cc:182] This TensorFlow binary is optimized to use available CPU instructions in performance-critical operations.\n",
      "To enable the following instructions: AVX2 FMA, in other operations, rebuild TensorFlow with the appropriate compiler flags.\n",
      "2023-06-07 07:06:23.168818: W tensorflow/compiler/tf2tensorrt/utils/py_utils.cc:38] TF-TRT Warning: Could not find TensorRT\n",
      "/opt/conda/envs/dove/lib/python3.11/site-packages/tqdm/auto.py:21: TqdmWarning: IProgress not found. Please update jupyter and ipywidgets. See https://ipywidgets.readthedocs.io/en/stable/user_install.html\n",
      "  from .autonotebook import tqdm as notebook_tqdm\n"
     ]
    }
   ],
   "source": [
    "import pathlib\n",
    "import os\n",
    "\n",
    "from tensorflow.keras.optimizers import Adam\n",
    "import tensorflow_datasets as tfds\n",
    "import tensorflow as tf\n",
    "\n",
    "from misc.CycleGANTraining import CycleGANTraining\n",
    "from misc.train_monitor import get_train_monitor\n",
    "from misc.data import read_train_sample\n",
    "from misc.data import read_test_sample\n",
    "from misc.model_tf import CycleGAN\n",
    "from misc import configs\n",
    "\n",
    "AUTO = tf.data.AUTOTUNE\n",
    "tf.random.set_seed(42)"
   ]
  },
  {
   "cell_type": "code",
   "execution_count": 2,
   "id": "fd4fa88b-01e2-4ef6-9d68-fbcdfca3701e",
   "metadata": {},
   "outputs": [
    {
     "name": "stderr",
     "output_type": "stream",
     "text": [
      "2023-06-07 07:06:29.578358: I tensorflow/core/common_runtime/gpu/gpu_device.cc:1635] Created device /job:localhost/replica:0/task:0/device:GPU:0 with 34441 MB memory:  -> device: 0, name: NVIDIA A100-SXM4-40GB, pci bus id: 0000:07:00.0, compute capability: 8.0\n",
      "2023-06-07 07:06:29.581322: I tensorflow/core/common_runtime/gpu/gpu_device.cc:1635] Created device /job:localhost/replica:0/task:0/device:GPU:1 with 38370 MB memory:  -> device: 1, name: NVIDIA A100-SXM4-40GB, pci bus id: 0000:0f:00.0, compute capability: 8.0\n",
      "2023-06-07 07:06:29.587507: I tensorflow/core/common_runtime/gpu/gpu_device.cc:1635] Created device /job:localhost/replica:0/task:0/device:GPU:2 with 38370 MB memory:  -> device: 2, name: NVIDIA A100-SXM4-40GB, pci bus id: 0000:47:00.0, compute capability: 8.0\n",
      "2023-06-07 07:06:29.590367: I tensorflow/core/common_runtime/gpu/gpu_device.cc:1635] Created device /job:localhost/replica:0/task:0/device:GPU:3 with 38370 MB memory:  -> device: 3, name: NVIDIA A100-SXM4-40GB, pci bus id: 0000:4e:00.0, compute capability: 8.0\n",
      "2023-06-07 07:06:29.592977: I tensorflow/core/common_runtime/gpu/gpu_device.cc:1635] Created device /job:localhost/replica:0/task:0/device:GPU:4 with 38370 MB memory:  -> device: 4, name: NVIDIA A100-SXM4-40GB, pci bus id: 0000:87:00.0, compute capability: 8.0\n",
      "2023-06-07 07:06:29.595663: I tensorflow/core/common_runtime/gpu/gpu_device.cc:1635] Created device /job:localhost/replica:0/task:0/device:GPU:5 with 38370 MB memory:  -> device: 5, name: NVIDIA A100-SXM4-40GB, pci bus id: 0000:90:00.0, compute capability: 8.0\n",
      "2023-06-07 07:06:29.598286: I tensorflow/core/common_runtime/gpu/gpu_device.cc:1635] Created device /job:localhost/replica:0/task:0/device:GPU:6 with 38370 MB memory:  -> device: 6, name: NVIDIA A100-SXM4-40GB, pci bus id: 0000:b7:00.0, compute capability: 8.0\n",
      "2023-06-07 07:06:29.600904: I tensorflow/core/common_runtime/gpu/gpu_device.cc:1635] Created device /job:localhost/replica:0/task:0/device:GPU:7 with 38370 MB memory:  -> device: 7, name: NVIDIA A100-SXM4-40GB, pci bus id: 0000:bd:00.0, compute capability: 8.0\n"
     ]
    }
   ],
   "source": [
    "## 데이터 셋 다운로드 받는 부분\n",
    "datasets = tfds.load('cycle_gan/apple2orange')\n",
    "(train_input, train_output) = datasets['trainA'], datasets['trainB']\n",
    "(test_input ,  test_output) = datasets['testA'] , datasets['testB'] \n",
    "\n",
    "def dataset_map(dataset, func, batch_size, dtype = 'train'): \n",
    "    \n",
    "    dataset = dataset.map(func, num_parallel_calls = AUTO)\n",
    "    dataset = dataset.shuffle(batch_size).batch(batch_size).repeat() if dtype == 'train' else dataset.shuffle(batch_size).batch(batch_size)\n",
    "    return dataset\n",
    "\n",
    "## 데이터 셋 전처리\n",
    "train_input  = dataset_map(train_input , read_train_sample, configs.TRAIN_BATCH_SIZE)\n",
    "train_output = dataset_map(train_output, read_train_sample, configs.TRAIN_BATCH_SIZE)\n",
    "\n",
    "test_input   = dataset_map(test_input  , read_test_sample, configs.INFER_BATCH_SIZE, dtype = 'test')\n",
    "test_output  = dataset_map(test_output , read_test_sample, configs.INFER_BATCH_SIZE, dtype = 'test')\n",
    "\n",
    "train_dataset = tf.data.Dataset.zip((train_input, train_output))\n",
    "loss          = tf.keras.losses.BinaryCrossentropy(from_logits = True)\n",
    "model         = CycleGAN(configs.IMG_HEIGHT, configs.IMG_WIDTH)"
   ]
  },
  {
   "cell_type": "code",
   "execution_count": 3,
   "id": "6f3ec296-1b21-4764-959d-6be8cfe16328",
   "metadata": {},
   "outputs": [
    {
     "name": "stdout",
     "output_type": "stream",
     "text": [
      "(None, 256, 256, 3)\n",
      "(None, 128, 128, 64)\n",
      "(None, 64, 64, 128)\n",
      "(None, 32, 32, 256)\n",
      "(None, 32, 32, 512)\n",
      "(None, 30, 30, 1)\n",
      "\n",
      "\n",
      "------------\n",
      "\n",
      "\n",
      "(None, 256, 256, 3)\n",
      "(None, 128, 128, 64)\n",
      "(None, 64, 64, 128)\n",
      "(None, 32, 32, 256)\n",
      "(None, 32, 32, 512)\n",
      "(None, 30, 30, 1)\n",
      "\n",
      "\n",
      "------------\n",
      "\n",
      "\n"
     ]
    },
    {
     "name": "stderr",
     "output_type": "stream",
     "text": [
      "2023-06-07 07:06:30.630293: I tensorflow/core/common_runtime/executor.cc:1197] [/device:CPU:0] (DEBUG INFO) Executor start aborting (this does not indicate an error and you can ignore this message): INVALID_ARGUMENT: You must feed a value for placeholder tensor 'Placeholder/_2' with dtype string and shape [1]\n",
      "\t [[{{node Placeholder/_2}}]]\n",
      "2023-06-07 07:06:30.630782: I tensorflow/core/common_runtime/executor.cc:1197] [/device:CPU:0] (DEBUG INFO) Executor start aborting (this does not indicate an error and you can ignore this message): INVALID_ARGUMENT: You must feed a value for placeholder tensor 'Placeholder/_1' with dtype string and shape [1]\n",
      "\t [[{{node Placeholder/_1}}]]\n",
      "2023-06-07 07:06:30.744070: W tensorflow/core/kernels/data/cache_dataset_ops.cc:856] The calling iterator did not fully read the dataset being cached. In order to avoid unexpected truncation of the dataset, the partially cached contents of the dataset  will be discarded. This can happen if you have an input pipeline similar to `dataset.cache().take(k).repeat()`. You should use `dataset.take(k).cache().repeat()` instead.\n",
      "2023-06-07 07:06:30.767314: I tensorflow/core/common_runtime/executor.cc:1197] [/device:CPU:0] (DEBUG INFO) Executor start aborting (this does not indicate an error and you can ignore this message): INVALID_ARGUMENT: You must feed a value for placeholder tensor 'Placeholder/_4' with dtype int64 and shape [1]\n",
      "\t [[{{node Placeholder/_4}}]]\n",
      "2023-06-07 07:06:30.767793: I tensorflow/core/common_runtime/executor.cc:1197] [/device:CPU:0] (DEBUG INFO) Executor start aborting (this does not indicate an error and you can ignore this message): INVALID_ARGUMENT: You must feed a value for placeholder tensor 'Placeholder/_4' with dtype int64 and shape [1]\n",
      "\t [[{{node Placeholder/_4}}]]\n",
      "2023-06-07 07:06:30.862417: W tensorflow/core/kernels/data/cache_dataset_ops.cc:856] The calling iterator did not fully read the dataset being cached. In order to avoid unexpected truncation of the dataset, the partially cached contents of the dataset  will be discarded. This can happen if you have an input pipeline similar to `dataset.cache().take(k).repeat()`. You should use `dataset.take(k).cache().repeat()` instead.\n"
     ]
    }
   ],
   "source": [
    "discX = model.discriminator()\n",
    "discY = model.discriminator()\n",
    "genG  = model.generator()\n",
    "genF  = model.generator()\n",
    "\n",
    "os.makedirs(configs.BASE_IMAGES_PATH, exist_ok = True)\n",
    "\n",
    "cycleGAN = CycleGANTraining(\n",
    "                    gen_G = genG, disc_X = discX,\n",
    "                    gen_F = genF, disc_Y = discY\n",
    "            )\n",
    "\n",
    "cycleGAN.compile(\n",
    "                    g_optimG = Adam(learning_rate = configs.LR),\n",
    "                    d_optimX = Adam(learning_rate = configs.LR),\n",
    "                    g_optimF = Adam(learning_rate = configs.LR),\n",
    "                    d_optimY = Adam(learning_rate = configs.LR),\n",
    "                    bceLoss  = loss\n",
    "                )\n",
    "\n",
    "callbacks = [get_train_monitor(test_input, test_output, epoch_interval = 10,\n",
    "                               image_path = configs.BASE_IMAGES_PATH,\n",
    "                               batch_size = configs.INFER_BATCH_SIZE)]"
   ]
  },
  {
   "cell_type": "code",
   "execution_count": 4,
   "id": "625388ad-3eb1-4248-b771-5e1f316db43d",
   "metadata": {},
   "outputs": [
    {
     "name": "stdout",
     "output_type": "stream",
     "text": [
      "Epoch 1/50\n"
     ]
    },
    {
     "name": "stderr",
     "output_type": "stream",
     "text": [
      "2023-06-07 07:06:30.899353: I tensorflow/core/common_runtime/executor.cc:1197] [/device:CPU:0] (DEBUG INFO) Executor start aborting (this does not indicate an error and you can ignore this message): INVALID_ARGUMENT: You must feed a value for placeholder tensor 'Placeholder/_2' with dtype string and shape [1]\n",
      "\t [[{{node Placeholder/_2}}]]\n",
      "2023-06-07 07:06:30.900083: I tensorflow/core/common_runtime/executor.cc:1197] [/device:CPU:0] (DEBUG INFO) Executor start aborting (this does not indicate an error and you can ignore this message): INVALID_ARGUMENT: You must feed a value for placeholder tensor 'Placeholder/_3' with dtype int64 and shape [1]\n",
      "\t [[{{node Placeholder/_3}}]]\n",
      "2023-06-07 07:06:36.949421: E tensorflow/core/grappler/optimizers/meta_optimizer.cc:954] layout failed: INVALID_ARGUMENT: Size of values 0 does not match size of permutation 4 @ fanin shape inmodel_2/dropout/dropout/SelectV2-2-TransposeNHWCToNCHW-LayoutOptimizer\n",
      "2023-06-07 07:06:38.839432: E tensorflow/compiler/xla/stream_executor/cuda/cuda_dnn.cc:417] Loaded runtime CuDNN library: 8.2.1 but source was compiled with: 8.6.0.  CuDNN library needs to have matching major version and equal or higher minor version. If using a binary install, upgrade your CuDNN library.  If building from sources, make sure the library loaded at runtime is compatible with the version specified during compile configuration.\n",
      "2023-06-07 07:06:38.843094: W tensorflow/core/framework/op_kernel.cc:1830] OP_REQUIRES failed at conv_ops.cc:1068 : UNIMPLEMENTED: DNN library is not found.\n",
      "2023-06-07 07:06:38.843137: I tensorflow/core/common_runtime/executor.cc:1197] [/job:localhost/replica:0/task:0/device:GPU:0] (DEBUG INFO) Executor start aborting (this does not indicate an error and you can ignore this message): UNIMPLEMENTED: DNN library is not found.\n",
      "\t [[{{node model_1/conv2d_5/Conv2D}}]]\n",
      "2023-06-07 07:06:38.854694: E tensorflow/compiler/xla/stream_executor/cuda/cuda_dnn.cc:417] Loaded runtime CuDNN library: 8.2.1 but source was compiled with: 8.6.0.  CuDNN library needs to have matching major version and equal or higher minor version. If using a binary install, upgrade your CuDNN library.  If building from sources, make sure the library loaded at runtime is compatible with the version specified during compile configuration.\n",
      "2023-06-07 07:06:38.857953: W tensorflow/core/framework/op_kernel.cc:1830] OP_REQUIRES failed at conv_ops_fused_impl.h:625 : UNIMPLEMENTED: DNN library is not found.\n",
      "2023-06-07 07:06:38.869715: E tensorflow/compiler/xla/stream_executor/cuda/cuda_dnn.cc:417] Loaded runtime CuDNN library: 8.2.1 but source was compiled with: 8.6.0.  CuDNN library needs to have matching major version and equal or higher minor version. If using a binary install, upgrade your CuDNN library.  If building from sources, make sure the library loaded at runtime is compatible with the version specified during compile configuration.\n",
      "2023-06-07 07:06:38.872936: W tensorflow/core/framework/op_kernel.cc:1830] OP_REQUIRES failed at conv_ops.cc:1068 : UNIMPLEMENTED: DNN library is not found.\n",
      "2023-06-07 07:06:38.884457: E tensorflow/compiler/xla/stream_executor/cuda/cuda_dnn.cc:417] Loaded runtime CuDNN library: 8.2.1 but source was compiled with: 8.6.0.  CuDNN library needs to have matching major version and equal or higher minor version. If using a binary install, upgrade your CuDNN library.  If building from sources, make sure the library loaded at runtime is compatible with the version specified during compile configuration.\n",
      "2023-06-07 07:06:38.887697: W tensorflow/core/framework/op_kernel.cc:1830] OP_REQUIRES failed at conv_ops_fused_impl.h:625 : UNIMPLEMENTED: DNN library is not found.\n",
      "2023-06-07 07:06:38.900467: E tensorflow/compiler/xla/stream_executor/cuda/cuda_dnn.cc:417] Loaded runtime CuDNN library: 8.2.1 but source was compiled with: 8.6.0.  CuDNN library needs to have matching major version and equal or higher minor version. If using a binary install, upgrade your CuDNN library.  If building from sources, make sure the library loaded at runtime is compatible with the version specified during compile configuration.\n",
      "2023-06-07 07:06:38.904073: W tensorflow/core/framework/op_kernel.cc:1830] OP_REQUIRES failed at conv_ops_fused_impl.h:625 : UNIMPLEMENTED: DNN library is not found.\n",
      "2023-06-07 07:06:38.916965: E tensorflow/compiler/xla/stream_executor/cuda/cuda_dnn.cc:417] Loaded runtime CuDNN library: 8.2.1 but source was compiled with: 8.6.0.  CuDNN library needs to have matching major version and equal or higher minor version. If using a binary install, upgrade your CuDNN library.  If building from sources, make sure the library loaded at runtime is compatible with the version specified during compile configuration.\n",
      "2023-06-07 07:06:38.920542: W tensorflow/core/framework/op_kernel.cc:1830] OP_REQUIRES failed at conv_ops_fused_impl.h:625 : UNIMPLEMENTED: DNN library is not found.\n"
     ]
    },
    {
     "ename": "UnimplementedError",
     "evalue": "Graph execution error:\n\nDetected at node 'model_1/conv2d_5/Conv2D' defined at (most recent call last):\n    File \"<frozen runpy>\", line 198, in _run_module_as_main\n    File \"<frozen runpy>\", line 88, in _run_code\n    File \"/opt/conda/envs/dove/lib/python3.11/site-packages/ipykernel_launcher.py\", line 17, in <module>\n      app.launch_new_instance()\n    File \"/opt/conda/envs/dove/lib/python3.11/site-packages/traitlets/config/application.py\", line 1043, in launch_instance\n      app.start()\n    File \"/opt/conda/envs/dove/lib/python3.11/site-packages/ipykernel/kernelapp.py\", line 725, in start\n      self.io_loop.start()\n    File \"/opt/conda/envs/dove/lib/python3.11/site-packages/tornado/platform/asyncio.py\", line 195, in start\n      self.asyncio_loop.run_forever()\n    File \"/opt/conda/envs/dove/lib/python3.11/asyncio/base_events.py\", line 607, in run_forever\n      self._run_once()\n    File \"/opt/conda/envs/dove/lib/python3.11/asyncio/base_events.py\", line 1922, in _run_once\n      handle._run()\n    File \"/opt/conda/envs/dove/lib/python3.11/asyncio/events.py\", line 80, in _run\n      self._context.run(self._callback, *self._args)\n    File \"/opt/conda/envs/dove/lib/python3.11/site-packages/ipykernel/kernelbase.py\", line 513, in dispatch_queue\n      await self.process_one()\n    File \"/opt/conda/envs/dove/lib/python3.11/site-packages/ipykernel/kernelbase.py\", line 502, in process_one\n      await dispatch(*args)\n    File \"/opt/conda/envs/dove/lib/python3.11/site-packages/ipykernel/kernelbase.py\", line 409, in dispatch_shell\n      await result\n    File \"/opt/conda/envs/dove/lib/python3.11/site-packages/ipykernel/kernelbase.py\", line 729, in execute_request\n      reply_content = await reply_content\n    File \"/opt/conda/envs/dove/lib/python3.11/site-packages/ipykernel/ipkernel.py\", line 422, in do_execute\n      res = shell.run_cell(\n    File \"/opt/conda/envs/dove/lib/python3.11/site-packages/ipykernel/zmqshell.py\", line 540, in run_cell\n      return super().run_cell(*args, **kwargs)\n    File \"/opt/conda/envs/dove/lib/python3.11/site-packages/IPython/core/interactiveshell.py\", line 3009, in run_cell\n      result = self._run_cell(\n    File \"/opt/conda/envs/dove/lib/python3.11/site-packages/IPython/core/interactiveshell.py\", line 3064, in _run_cell\n      result = runner(coro)\n    File \"/opt/conda/envs/dove/lib/python3.11/site-packages/IPython/core/async_helpers.py\", line 129, in _pseudo_sync_runner\n      coro.send(None)\n    File \"/opt/conda/envs/dove/lib/python3.11/site-packages/IPython/core/interactiveshell.py\", line 3269, in run_cell_async\n      has_raised = await self.run_ast_nodes(code_ast.body, cell_name,\n    File \"/opt/conda/envs/dove/lib/python3.11/site-packages/IPython/core/interactiveshell.py\", line 3448, in run_ast_nodes\n      if await self.run_code(code, result, async_=asy):\n    File \"/opt/conda/envs/dove/lib/python3.11/site-packages/IPython/core/interactiveshell.py\", line 3508, in run_code\n      exec(code_obj, self.user_global_ns, self.user_ns)\n    File \"/tmp/ipykernel_2794490/451847961.py\", line 1, in <module>\n      cycleGAN.fit(train_dataset, epochs = configs.EPOCHS, callbacks = callbacks,\n    File \"/opt/conda/envs/dove/lib/python3.11/site-packages/keras/utils/traceback_utils.py\", line 65, in error_handler\n      return fn(*args, **kwargs)\n    File \"/opt/conda/envs/dove/lib/python3.11/site-packages/keras/engine/training.py\", line 1685, in fit\n      tmp_logs = self.train_function(iterator)\n    File \"/opt/conda/envs/dove/lib/python3.11/site-packages/keras/engine/training.py\", line 1284, in train_function\n      return step_function(self, iterator)\n    File \"/opt/conda/envs/dove/lib/python3.11/site-packages/keras/engine/training.py\", line 1268, in step_function\n      outputs = model.distribute_strategy.run(run_step, args=(data,))\n    File \"/opt/conda/envs/dove/lib/python3.11/site-packages/keras/engine/training.py\", line 1249, in run_step\n      outputs = model.train_step(data)\n    File \"/home/jovyan/NVIDIA_CUDA-11.1_Samples/TIL/AI_study/Generative Model/GANs/misc/CycleGANTraining.py\", line 45, in train_step\n      disc_real_outY = self.disc_Y([target_image], training = True)\n    File \"/opt/conda/envs/dove/lib/python3.11/site-packages/keras/utils/traceback_utils.py\", line 65, in error_handler\n      return fn(*args, **kwargs)\n    File \"/opt/conda/envs/dove/lib/python3.11/site-packages/keras/engine/training.py\", line 558, in __call__\n      return super().__call__(*args, **kwargs)\n    File \"/opt/conda/envs/dove/lib/python3.11/site-packages/keras/utils/traceback_utils.py\", line 65, in error_handler\n      return fn(*args, **kwargs)\n    File \"/opt/conda/envs/dove/lib/python3.11/site-packages/keras/engine/base_layer.py\", line 1145, in __call__\n      outputs = call_fn(inputs, *args, **kwargs)\n    File \"/opt/conda/envs/dove/lib/python3.11/site-packages/keras/utils/traceback_utils.py\", line 96, in error_handler\n      return fn(*args, **kwargs)\n    File \"/opt/conda/envs/dove/lib/python3.11/site-packages/keras/engine/functional.py\", line 512, in call\n      return self._run_internal_graph(inputs, training=training, mask=mask)\n    File \"/opt/conda/envs/dove/lib/python3.11/site-packages/keras/engine/functional.py\", line 669, in _run_internal_graph\n      outputs = node.layer(*args, **kwargs)\n    File \"/opt/conda/envs/dove/lib/python3.11/site-packages/keras/utils/traceback_utils.py\", line 65, in error_handler\n      return fn(*args, **kwargs)\n    File \"/opt/conda/envs/dove/lib/python3.11/site-packages/keras/engine/base_layer.py\", line 1145, in __call__\n      outputs = call_fn(inputs, *args, **kwargs)\n    File \"/opt/conda/envs/dove/lib/python3.11/site-packages/keras/utils/traceback_utils.py\", line 96, in error_handler\n      return fn(*args, **kwargs)\n    File \"/opt/conda/envs/dove/lib/python3.11/site-packages/keras/layers/convolutional/base_conv.py\", line 290, in call\n      outputs = self.convolution_op(inputs, self.kernel)\n    File \"/opt/conda/envs/dove/lib/python3.11/site-packages/keras/layers/convolutional/base_conv.py\", line 262, in convolution_op\n      return tf.nn.convolution(\nNode: 'model_1/conv2d_5/Conv2D'\nDNN library is not found.\n\t [[{{node model_1/conv2d_5/Conv2D}}]] [Op:__inference_train_function_16762]",
     "output_type": "error",
     "traceback": [
      "\u001b[0;31m---------------------------------------------------------------------------\u001b[0m",
      "\u001b[0;31mUnimplementedError\u001b[0m                        Traceback (most recent call last)",
      "Cell \u001b[0;32mIn[4], line 1\u001b[0m\n\u001b[0;32m----> 1\u001b[0m \u001b[43mcycleGAN\u001b[49m\u001b[38;5;241;43m.\u001b[39;49m\u001b[43mfit\u001b[49m\u001b[43m(\u001b[49m\u001b[43mtrain_dataset\u001b[49m\u001b[43m,\u001b[49m\u001b[43m \u001b[49m\u001b[43mepochs\u001b[49m\u001b[43m \u001b[49m\u001b[38;5;241;43m=\u001b[39;49m\u001b[43m \u001b[49m\u001b[43mconfigs\u001b[49m\u001b[38;5;241;43m.\u001b[39;49m\u001b[43mEPOCHS\u001b[49m\u001b[43m,\u001b[49m\u001b[43m \u001b[49m\u001b[43mcallbacks\u001b[49m\u001b[43m \u001b[49m\u001b[38;5;241;43m=\u001b[39;49m\u001b[43m \u001b[49m\u001b[43mcallbacks\u001b[49m\u001b[43m,\u001b[49m\n\u001b[1;32m      2\u001b[0m \u001b[43m             \u001b[49m\u001b[43msteps_per_epoch\u001b[49m\u001b[43m \u001b[49m\u001b[38;5;241;43m=\u001b[39;49m\u001b[43m \u001b[49m\u001b[43mconfigs\u001b[49m\u001b[38;5;241;43m.\u001b[39;49m\u001b[43mSTEPS_PER_EPOCH\u001b[49m\u001b[43m)\u001b[49m\n\u001b[1;32m      4\u001b[0m cycleGAN\u001b[38;5;241m.\u001b[39mgen_G\u001b[38;5;241m.\u001b[39msave(config\u001b[38;5;241m.\u001b[39mGENERATOR_MODEL)\n",
      "File \u001b[0;32m/opt/conda/envs/dove/lib/python3.11/site-packages/keras/utils/traceback_utils.py:70\u001b[0m, in \u001b[0;36mfilter_traceback.<locals>.error_handler\u001b[0;34m(*args, **kwargs)\u001b[0m\n\u001b[1;32m     67\u001b[0m     filtered_tb \u001b[38;5;241m=\u001b[39m _process_traceback_frames(e\u001b[38;5;241m.\u001b[39m__traceback__)\n\u001b[1;32m     68\u001b[0m     \u001b[38;5;66;03m# To get the full stack trace, call:\u001b[39;00m\n\u001b[1;32m     69\u001b[0m     \u001b[38;5;66;03m# `tf.debugging.disable_traceback_filtering()`\u001b[39;00m\n\u001b[0;32m---> 70\u001b[0m     \u001b[38;5;28;01mraise\u001b[39;00m e\u001b[38;5;241m.\u001b[39mwith_traceback(filtered_tb) \u001b[38;5;28;01mfrom\u001b[39;00m \u001b[38;5;28;01mNone\u001b[39;00m\n\u001b[1;32m     71\u001b[0m \u001b[38;5;28;01mfinally\u001b[39;00m:\n\u001b[1;32m     72\u001b[0m     \u001b[38;5;28;01mdel\u001b[39;00m filtered_tb\n",
      "File \u001b[0;32m/opt/conda/envs/dove/lib/python3.11/site-packages/tensorflow/python/eager/execute.py:52\u001b[0m, in \u001b[0;36mquick_execute\u001b[0;34m(op_name, num_outputs, inputs, attrs, ctx, name)\u001b[0m\n\u001b[1;32m     50\u001b[0m \u001b[38;5;28;01mtry\u001b[39;00m:\n\u001b[1;32m     51\u001b[0m   ctx\u001b[38;5;241m.\u001b[39mensure_initialized()\n\u001b[0;32m---> 52\u001b[0m   tensors \u001b[38;5;241m=\u001b[39m pywrap_tfe\u001b[38;5;241m.\u001b[39mTFE_Py_Execute(ctx\u001b[38;5;241m.\u001b[39m_handle, device_name, op_name,\n\u001b[1;32m     53\u001b[0m                                       inputs, attrs, num_outputs)\n\u001b[1;32m     54\u001b[0m \u001b[38;5;28;01mexcept\u001b[39;00m core\u001b[38;5;241m.\u001b[39m_NotOkStatusException \u001b[38;5;28;01mas\u001b[39;00m e:\n\u001b[1;32m     55\u001b[0m   \u001b[38;5;28;01mif\u001b[39;00m name \u001b[38;5;129;01mis\u001b[39;00m \u001b[38;5;129;01mnot\u001b[39;00m \u001b[38;5;28;01mNone\u001b[39;00m:\n",
      "\u001b[0;31mUnimplementedError\u001b[0m: Graph execution error:\n\nDetected at node 'model_1/conv2d_5/Conv2D' defined at (most recent call last):\n    File \"<frozen runpy>\", line 198, in _run_module_as_main\n    File \"<frozen runpy>\", line 88, in _run_code\n    File \"/opt/conda/envs/dove/lib/python3.11/site-packages/ipykernel_launcher.py\", line 17, in <module>\n      app.launch_new_instance()\n    File \"/opt/conda/envs/dove/lib/python3.11/site-packages/traitlets/config/application.py\", line 1043, in launch_instance\n      app.start()\n    File \"/opt/conda/envs/dove/lib/python3.11/site-packages/ipykernel/kernelapp.py\", line 725, in start\n      self.io_loop.start()\n    File \"/opt/conda/envs/dove/lib/python3.11/site-packages/tornado/platform/asyncio.py\", line 195, in start\n      self.asyncio_loop.run_forever()\n    File \"/opt/conda/envs/dove/lib/python3.11/asyncio/base_events.py\", line 607, in run_forever\n      self._run_once()\n    File \"/opt/conda/envs/dove/lib/python3.11/asyncio/base_events.py\", line 1922, in _run_once\n      handle._run()\n    File \"/opt/conda/envs/dove/lib/python3.11/asyncio/events.py\", line 80, in _run\n      self._context.run(self._callback, *self._args)\n    File \"/opt/conda/envs/dove/lib/python3.11/site-packages/ipykernel/kernelbase.py\", line 513, in dispatch_queue\n      await self.process_one()\n    File \"/opt/conda/envs/dove/lib/python3.11/site-packages/ipykernel/kernelbase.py\", line 502, in process_one\n      await dispatch(*args)\n    File \"/opt/conda/envs/dove/lib/python3.11/site-packages/ipykernel/kernelbase.py\", line 409, in dispatch_shell\n      await result\n    File \"/opt/conda/envs/dove/lib/python3.11/site-packages/ipykernel/kernelbase.py\", line 729, in execute_request\n      reply_content = await reply_content\n    File \"/opt/conda/envs/dove/lib/python3.11/site-packages/ipykernel/ipkernel.py\", line 422, in do_execute\n      res = shell.run_cell(\n    File \"/opt/conda/envs/dove/lib/python3.11/site-packages/ipykernel/zmqshell.py\", line 540, in run_cell\n      return super().run_cell(*args, **kwargs)\n    File \"/opt/conda/envs/dove/lib/python3.11/site-packages/IPython/core/interactiveshell.py\", line 3009, in run_cell\n      result = self._run_cell(\n    File \"/opt/conda/envs/dove/lib/python3.11/site-packages/IPython/core/interactiveshell.py\", line 3064, in _run_cell\n      result = runner(coro)\n    File \"/opt/conda/envs/dove/lib/python3.11/site-packages/IPython/core/async_helpers.py\", line 129, in _pseudo_sync_runner\n      coro.send(None)\n    File \"/opt/conda/envs/dove/lib/python3.11/site-packages/IPython/core/interactiveshell.py\", line 3269, in run_cell_async\n      has_raised = await self.run_ast_nodes(code_ast.body, cell_name,\n    File \"/opt/conda/envs/dove/lib/python3.11/site-packages/IPython/core/interactiveshell.py\", line 3448, in run_ast_nodes\n      if await self.run_code(code, result, async_=asy):\n    File \"/opt/conda/envs/dove/lib/python3.11/site-packages/IPython/core/interactiveshell.py\", line 3508, in run_code\n      exec(code_obj, self.user_global_ns, self.user_ns)\n    File \"/tmp/ipykernel_2794490/451847961.py\", line 1, in <module>\n      cycleGAN.fit(train_dataset, epochs = configs.EPOCHS, callbacks = callbacks,\n    File \"/opt/conda/envs/dove/lib/python3.11/site-packages/keras/utils/traceback_utils.py\", line 65, in error_handler\n      return fn(*args, **kwargs)\n    File \"/opt/conda/envs/dove/lib/python3.11/site-packages/keras/engine/training.py\", line 1685, in fit\n      tmp_logs = self.train_function(iterator)\n    File \"/opt/conda/envs/dove/lib/python3.11/site-packages/keras/engine/training.py\", line 1284, in train_function\n      return step_function(self, iterator)\n    File \"/opt/conda/envs/dove/lib/python3.11/site-packages/keras/engine/training.py\", line 1268, in step_function\n      outputs = model.distribute_strategy.run(run_step, args=(data,))\n    File \"/opt/conda/envs/dove/lib/python3.11/site-packages/keras/engine/training.py\", line 1249, in run_step\n      outputs = model.train_step(data)\n    File \"/home/jovyan/NVIDIA_CUDA-11.1_Samples/TIL/AI_study/Generative Model/GANs/misc/CycleGANTraining.py\", line 45, in train_step\n      disc_real_outY = self.disc_Y([target_image], training = True)\n    File \"/opt/conda/envs/dove/lib/python3.11/site-packages/keras/utils/traceback_utils.py\", line 65, in error_handler\n      return fn(*args, **kwargs)\n    File \"/opt/conda/envs/dove/lib/python3.11/site-packages/keras/engine/training.py\", line 558, in __call__\n      return super().__call__(*args, **kwargs)\n    File \"/opt/conda/envs/dove/lib/python3.11/site-packages/keras/utils/traceback_utils.py\", line 65, in error_handler\n      return fn(*args, **kwargs)\n    File \"/opt/conda/envs/dove/lib/python3.11/site-packages/keras/engine/base_layer.py\", line 1145, in __call__\n      outputs = call_fn(inputs, *args, **kwargs)\n    File \"/opt/conda/envs/dove/lib/python3.11/site-packages/keras/utils/traceback_utils.py\", line 96, in error_handler\n      return fn(*args, **kwargs)\n    File \"/opt/conda/envs/dove/lib/python3.11/site-packages/keras/engine/functional.py\", line 512, in call\n      return self._run_internal_graph(inputs, training=training, mask=mask)\n    File \"/opt/conda/envs/dove/lib/python3.11/site-packages/keras/engine/functional.py\", line 669, in _run_internal_graph\n      outputs = node.layer(*args, **kwargs)\n    File \"/opt/conda/envs/dove/lib/python3.11/site-packages/keras/utils/traceback_utils.py\", line 65, in error_handler\n      return fn(*args, **kwargs)\n    File \"/opt/conda/envs/dove/lib/python3.11/site-packages/keras/engine/base_layer.py\", line 1145, in __call__\n      outputs = call_fn(inputs, *args, **kwargs)\n    File \"/opt/conda/envs/dove/lib/python3.11/site-packages/keras/utils/traceback_utils.py\", line 96, in error_handler\n      return fn(*args, **kwargs)\n    File \"/opt/conda/envs/dove/lib/python3.11/site-packages/keras/layers/convolutional/base_conv.py\", line 290, in call\n      outputs = self.convolution_op(inputs, self.kernel)\n    File \"/opt/conda/envs/dove/lib/python3.11/site-packages/keras/layers/convolutional/base_conv.py\", line 262, in convolution_op\n      return tf.nn.convolution(\nNode: 'model_1/conv2d_5/Conv2D'\nDNN library is not found.\n\t [[{{node model_1/conv2d_5/Conv2D}}]] [Op:__inference_train_function_16762]"
     ]
    }
   ],
   "source": [
    "cycleGAN.fit(train_dataset, epochs = configs.EPOCHS, callbacks = callbacks,\n",
    "             steps_per_epoch = configs.STEPS_PER_EPOCH)\n",
    "\n",
    "cycleGAN.gen_G.save(config.GENERATOR_MODEL)"
   ]
  }
 ],
 "metadata": {
  "kernelspec": {
   "display_name": "dove",
   "language": "python",
   "name": "dove"
  },
  "language_info": {
   "codemirror_mode": {
    "name": "ipython",
    "version": 3
   },
   "file_extension": ".py",
   "mimetype": "text/x-python",
   "name": "python",
   "nbconvert_exporter": "python",
   "pygments_lexer": "ipython3",
   "version": "3.11.3"
  }
 },
 "nbformat": 4,
 "nbformat_minor": 5
}
